Epoch 1/10:   0%|                                                                               | 0/904 [00:02<?, ?it/s]
Traceback (most recent call last):
  File "/home/user/1024_whs/IVfusion_method1/model/stage2/train.py", line 354, in <module>
    main(**config_dic)
  File "/home/user/1024_whs/IVfusion_method1/model/stage2/train.py", line 317, in main
    best_epoch, best_loss = train_model(
                            ^^^^^^^^^^^^
  File "/home/user/1024_whs/IVfusion_method1/model/stage2/train.py", line 90, in train_model
    epoch_loss = train_epoch_model(model, train_loader, criterion, optimizer, device_1, device_2, device_3, val_loader, pbar)
                 ^^^^^^^^^^^^^^^^^^^^^^^^^^^^^^^^^^^^^^^^^^^^^^^^^^^^^^^^^^^^^^^^^^^^^^^^^^^^^^^^^^^^^^^^^^^^^^^^^^^^^^^^^^^^
  File "/home/user/1024_whs/IVfusion_method1/model/stage2/train.py", line 36, in train_epoch_model
    loss_all= criterion(output, i_image, v_image, l, g, mu_l, sigma2_l, mu_g, sigma2_g)
              ^^^^^^^^^^^^^^^^^^^^^^^^^^^^^^^^^^^^^^^^^^^^^^^^^^^^^^^^^^^^^^^^^^^^^^^^^
  File "/opt/conda/lib/python3.11/site-packages/torch/nn/modules/module.py", line 1751, in _wrapped_call_impl
    return self._call_impl(*args, **kwargs)
           ^^^^^^^^^^^^^^^^^^^^^^^^^^^^^^^^
  File "/opt/conda/lib/python3.11/site-packages/torch/nn/modules/module.py", line 1762, in _call_impl
    return forward_call(*args, **kwargs)
           ^^^^^^^^^^^^^^^^^^^^^^^^^^^^^
TypeError: Loss.forward() takes 8 positional arguments but 10 were given
